Traceback (most recent call last):
  File "<frozen runpy>", line 198, in _run_module_as_main
  File "<frozen runpy>", line 88, in _run_code
  File "/lfs/hyperturing1/0/echoi1/Random-SignNet/GINESignNetPyG/train/zinc.py", line 111, in <module>
    run(config_path, cfg, create_dataset, create_model, train, test)
  File "/lfs/hyperturing1/0/echoi1/Random-SignNet/GINESignNetPyG/core/train.py", line 35, in run
    model = create_model(cfg).to(cfg.device)
            ^^^^^^^^^^^^^^^^^
  File "/lfs/hyperturing1/0/echoi1/Random-SignNet/GINESignNetPyG/train/zinc.py", line 45, in create_model
    bn=cfg.model.bn,
       ^^^^^^^^^^^^
  File "/lfs/hyperturing1/0/echoi1/env/micromamba/envs/graphenv/lib/python3.11/site-packages/yacs/config.py", line 141, in __getattr__
    raise AttributeError(name)
AttributeError: bn